Workbook

Sheet covariateCoefsNew
B1: V1 | C1: V2 | D1: V3
A2: 1 | B2: 1.02 | C2: 0.55 | D2: 1.99 | F2: =_xlfn.CONCAT(B2, " ( ", C2, ", ", D2, ")") -> 1.02 ( 0.55, 1.99)
A3: 2 | B3: 1.84 | C3: 0.92 | D3: 3.79 | F3: =_xlfn.CONCAT(B3, " ( ", C3, ", ", D3, ")") -> 1.84 ( 0.92, 3.79)
A4: 3 | B4: 1.27 | C4: 0.49 | D4: 3.47 | F4: =_xlfn.CONCAT(B4, " ( ", C4, ", ", D4, ")") -> 1.27 ( 0.49, 3.47)
A5: 4 | B5: 2.76 | C5: 0.89 | D5: 8.13 | F5: =_xlfn.CONCAT(B5, " ( ", C5, ", ", D5, ")") -> 2.76 ( 0.89, 8.13)
A6: 5 | B6: 9.23 | C6: 1.16 | D6: 87.58 | F6: =_xlfn.CONCAT(B6, " ( ", C6, ", ", D6, ")") -> 9.23 ( 1.16, 87.58)
A7: 6 | B7: 7.26 | C7: 2.83 | D7: 17.68 | F7: =_xlfn.CONCAT(B7, " ( ", C7, ", ", D7, ")") -> 7.26 ( 2.83, 17.68)
A8: 7 | B8: 4.69 | C8: 1.67 | D8: 22.09 | F8: =_xlfn.CONCAT(B8, " ( ", C8, ", ", D8, ")") -> 4.69 ( 1.67, 22.09)
A9: 8 | B9: 7.89 | C9: 3.1 | D9: 16.56 | F9: =_xlfn.CONCAT(B9, " ( ", C9, ", ", D9, ")") -> 7.89 ( 3.1, 16.56)
A10: 9 | B10: 7.25 | C10: 3.05 | D10: 16.36 | F10: =_xlfn.CONCAT(B10, " ( ", C10, ", ", D10, ")") -> 7.25 ( 3.05, 16.36)
A11: 10 | B11: 1.18 | C11: 0.85 | D11: 1.63 | F11: =_xlfn.CONCAT(B11, " ( ", C11, ", ", D11, ")") -> 1.18 ( 0.85, 1.63)
A12: 11 | B12: 1.07 | C12: 0.81 | D12: 1.39 | F12: =_xlfn.CONCAT(B12, " ( ", C12, ", ", D12, ")") -> 1.07 ( 0.81, 1.39)
A13: 12 | B13: 1.38 | C13: 0.92 | D13: 2.4 | F13: =_xlfn.CONCAT(B13, " ( ", C13, ", ", D13, ")") -> 1.38 ( 0.92, 2.4)
... A46: 45 | B46: 0.86 | C46: 0.46 | D46: 1.57 | F46: =_xlfn.CONCAT(B46, " ( ", C46, ", ", D46, ")") -> 0.86 ( 0.46, 1.57)

Sheet formatted
B3: Pre-treatment phase
B4: Direct medical | C4: Direct non-medical | D4: Indirect
A5: RR/MDR-TB | B5: =covariateCoefsNew!F2 -> 1.02 ( 0.55, 1.99) | C5: =covariateCoefsNew!F3 -> 1.84 ( 0.92, 3.79) | D5: =covariateCoefsNew!F4 -> 1.27 ( 0.49, 3.47)
A6: Year | B6: =covariateCoefsNew!F11 -> 1.18 ( 0.85, 1.63) | C6: =covariateCoefsNew!F12 -> 1.07 ( 0.81, 1.39) | D6: =covariateCoefsNew!F13 -> 1.38 ( 0.92, 2.4)
A7: Median income | B7: =covariateCoefsNew!F20 -> 2.18 ( 1.2, 3.89) | C7: =covariateCoefsNew!F21 -> 1.59 ( 0.87, 2.78) | D7: =covariateCoefsNew!F22 -> 1.56 ( 0.84, 3.02)
A8: OOP % CHE | B8: =covariateCoefsNew!F29 -> 1.66 ( 1.13, 2.39) | C8: =covariateCoefsNew!F30 -> 1.41 ( 1.01, 1.9) | D8: =covariateCoefsNew!F31 -> 1.18 ( 0.8, 1.77)
A9: UHC index | B9: =covariateCoefsNew!F38 -> 0.85 ( 0.48, 1.58) | C9: =covariateCoefsNew!F39 -> 0.81 ( 0.46, 1.43) | D9: =covariateCoefsNew!F40 -> 0.81 ( 0.44, 1.44)
B11: Intensive treatment phase
B12: Direct medical | C12: Direct non-medical | D12: Indirect
A13: RR/MDR-TB | B13: =covariateCoefsNew!F5 -> 2.76 ( 0.89, 8.13) | C13: =covariateCoefsNew!F6 -> 9.23 ( 1.16, 87.58) | D13: =covariateCoefsNew!F7 -> 7.26 ( 2.83, 17.68)
A14: Year | B14: =covariateCoefsNew!F14 -> 0.96 ( 0.55, 1.45) | C14: =covariateCoefsNew!F15 -> 1 ( 0.4, 2.02) | D14: =covariateCoefsNew!F16 -> 0.98 ( 0.5, 1.43)
A15: Median income | B15: =covariateCoefsNew!F23 -> 1.91 ( 0.97, 4.75) | C15: =covariateCoefsNew!F24 -> 1.69 ( 0.62, 5.3) | D15: =covariateCoefsNew!F25 -> 2.16 ( 0.98, 4.96)
A16: OOP % CHE | B16: =covariateCoefsNew!F32 -> 1.31 ( 0.77, 2.46) | C16: =covariateCoefsNew!F33 -> 0.89 ( 0.26, 2.08) | D16: =covariateCoefsNew!F34 -> 0.76 ( 0.45, 1.2)
A17: UHC index | B17: =covariateCoefsNew!F41 -> 0.78 ( 0.37, 1.38) | C17: =covariateCoefsNew!F42 -> 0.82 ( 0.43, 1.7) | D17: =covariateCoefsNew!F43 -> 0.86 ( 0.45, 1.63)
B19: Continuation treatment phase
B20: Direct medical | C20: Direct non-medical | D20: Indirect
A21: RR/MDR-TB | B21: =covariateCoefsNew!F8 -> 4.69 ( 1.67, 22.09) | C21: =covariateCoefsNew!F9 -> 7.89 ( 3.1, 16.56) | D21: =covariateCoefsNew!F10 -> 7.25 ( 3.05, 16.36)
A22: Year | B22: =covariateCoefsNew!F17 -> 1.01 ( 0.6, 1.58) | C22: =covariateCoefsNew!F18 -> 1.04 ( 0.64, 1.46) | D22: =covariateCoefsNew!F19 -> 1.08 ( 0.67, 1.66)
A23: Median income | B23: =covariateCoefsNew!F26 -> 3.35 ( 1.27, 23.65) | C23: =covariateCoefsNew!F27 -> 1.25 ( 0.63, 2.55) | D23: =covariateCoefsNew!F28 -> 1.63 ( 0.81, 3.28)
A24: OOP % CHE | B24: =covariateCoefsNew!F35 -> 1.26 ( 0.65, 2.67) | C24: =covariateCoefsNew!F36 -> 0.61 ( 0.37, 1.11) | D24: =covariateCoefsNew!F37 -> 0.75 ( 0.49, 1.18)
A25: UHC index | B25: =covariateCoefsNew!F44 -> 0.86 ( 0.47, 2.11) | C25: =covariateCoefsNew!F45 -> 0.81 ( 0.42, 1.47) | D25: =covariateCoefsNew!F46 -> 0.86 ( 0.46, 1.57)

Sheet toolformat
A2: beta_drtb_overall
A3: beta_drtb_dme_prediag | B3: =covariateCoefsNew!B2 -> 1.02
A4: beta_drtb_dnme_prediag | B4: =covariateCoefsNew!B3 -> 1.84
A5: beta_drtb_ie_prediag | B5: =covariateCoefsNew!B4 -> 1.27
A6: beta_drtb_dme_intsvtx | B6: =covariateCoefsNew!B5 -> 2.76
A7: beta_drtb_dnme_intsvtx | B7: =covariateCoefsNew!B6 -> 9.23
A8: beta_drtb_ie_intsvtx | B8: =covariateCoefsNew!B7 -> 7.26
A9: beta_drtb_dme_contntx | B9: =covariateCoefsNew!B8 -> 4.69
A10: beta_drtb_dnme_contntx | B10: =covariateCoefsNew!B9 -> 7.89
A11: beta_drtb_ie_contntx | B11: =covariateCoefsNew!B10 -> 7.25
A12: beta_year_overall
A13: beta_year_dme_prediag | B13: =covariateCoefsNew!B11 -> 1.18
A14: beta_year_dnme_prediag | B14: =covariateCoefsNew!B12 -> 1.07
A15: beta_year_ie_prediag | B15: =covariateCoefsNew!B13 -> 1.38
A16: beta_year_dme_intsvtx | B16: =covariateCoefsNew!B14 -> 0.96
A17: beta_year_dnme_intsvtx | B17: =covariateCoefsNew!B15 -> 1
A18: beta_year_ie_intsvtx | B18: =covariateCoefsNew!B16 -> 0.98
A19: beta_year_dme_contntx | B19: =covariateCoefsNew!B17 -> 1.01
A20: beta_year_dnme_contntx | B20: =covariateCoefsNew!B18 -> 1.04
A21: beta_year_ie_contntx | B21: =covariateCoefsNew!B19 -> 1.08
A22: beta_world_region
A23: beta_med_income_overall
A24: beta_med_income_dme_prediag | B24: =covariateCoefsNew!B20 -> 2.18
A25: beta_med_income_dnme_prediag | B25: =covariateCoefsNew!B21 -> 1.59
A26: beta_med_income_ie_prediag | B26: =covariateCoefsNew!B22 -> 1.56
A27: beta_med_income_dme_intsvtx | B27: =covariateCoefsNew!B23 -> 1.91
A28: beta_med_income_dnme_intsvtx | B28: =covariateCoefsNew!B24 -> 1.69
A29: beta_med_income_ie_intsvtx | B29: =covariateCoefsNew!B25 -> 2.16
A30: beta_med_income_dme_contntx | B30: =covariateCoefsNew!B26 -> 3.35
A31: beta_med_income_dnme_contntx | B31: =covariateCoefsNew!B27 -> 1.25
A32: beta_med_income_ie_contntx | B32: =covariateCoefsNew!B28 -> 1.63
A33: beta_oop_che_overall
A34: beta_oop_che_dme_prediag | B34: =covariateCoefsNew!B29 -> 1.66
A35: beta_oop_che_dnme_prediag | B35: =covariateCoefsNew!B30 -> 1.41
A36: beta_oop_che_ie_prediag | B36: =covariateCoefsNew!B31 -> 1.18
A37: beta_oop_che_dme_intsvtx | B37: =covariateCoefsNew!B32 -> 1.31
A38: beta_oop_che_dnme_intsvtx | B38: =covariateCoefsNew!B33 -> 0.89
A39: beta_oop_che_ie_intsvtx | B39: =covariateCoefsNew!B34 -> 0.76
A40: beta_oop_che_dme_contntx | B40: =covariateCoefsNew!B35 -> 1.26
A41: beta_oop_che_dnme_contntx | B41: =covariateCoefsNew!B36 -> 0.61
...
